Workbook

Sheet Start
A1: Swiss Budget Planner 2026
A2: Excel & Google Sheets · in CHF · for singles, couples and families
A4: How it works
A5: 1. | B5: «Budget» sheet: enter your planned monthly budget in column B.
A6: 2. | B6: Each month, enter your actual amounts in that month's column (yellow cells).
A7: 3. | B7: Balance, savings rate and deviations are calculated automatically – red = over budget.
A8: 4. | B8: «Annual overview» charts income vs. expenses.
A9: 5. | B9: «Emergency fund», «Pillar 3a» and «Tax reserve» help you build reserves.
A11: Tips
A12: • | B12: Rename categories freely – the formulas keep working.
A13: • | B13: Divide annual bills (e.g. Serafe, insurance) by 12 and set the amount aside monthly.
A14: • | B14: Google Sheets: File → Import → Upload. Everything works without macros.
A16: Note
B17: This template is a planning tool, not tax or financial advice.

Sheet Budget
A1: Swiss Budget Planner 2026
A2: Fill in the yellow cells – everything else is calculated automatically.
A4: Category | B4: Budget / month | C4: Jan | D4: Feb | E4: Mar | F4: Apr | G4: May | H4: Jun | I4: Jul | J4: Aug | K4: Sep | L4: Oct | M4: Nov | N4: Dec | O4: Year total | P4: Ø month | Q4: Ø vs. budget
A5: INCOME
A6: Net salary | O6: =SUM(C6:N6) | P6: =IFERROR(AVERAGE(C6:N6),0) | Q6: =P6-B6
A7: 13th month salary / bonus | O7: =SUM(C7:N7) | P7: =IFERROR(AVERAGE(C7:N7),0) | Q7: =P7-B7
A8: Side income | O8: =SUM(C8:N8) | P8: =IFERROR(AVERAGE(C8:N8),0) | Q8: =P8-B8
A9: Child / family allowances | O9: =SUM(C9:N9) | P9: =IFERROR(AVERAGE(C9:N9),0) | Q9: =P9-B9
A10: Other income | O10: =SUM(C10:N10) | P10: =IFERROR(AVERAGE(C10:N10),0) | Q10: =P10-B10
A11: EXPENSES – HOUSING
A12: Rent / mortgage interest | O12: =SUM(C12:N12) | P12: =IFERROR(AVERAGE(C12:N12),0) | Q12: =P12-B12
A13: Service charges (Nebenkosten) | O13: =SUM(C13:N13) | P13: =IFERROR(AVERAGE(C13:N13),0) | Q13: =P13-B13
A14: Electricity | O14: =SUM(C14:N14) | P14: =IFERROR(AVERAGE(C14:N14),0) | Q14: =P14-B14
A15: Internet & mobile | O15: =SUM(C15:N15) | P15: =IFERROR(AVERAGE(C15:N15),0) | Q15: =P15-B15
A16: Serafe (radio/TV fee) | O16: =SUM(C16:N16) | P16: =IFERROR(AVERAGE(C16:N16),0) | Q16: =P16-B16
A17: Household contents & liability insurance | O17: =SUM(C17:N17) | P17: =IFERROR(AVERAGE(C17:N17),0) | Q17: =P17-B17
A18: EXPENSES – HEALTH
A19: Health insurance (basic / LAMal) | O19: =SUM(C19:N19) | P19: =IFERROR(AVERAGE(C19:N19),0) | Q19: =P19-B19
A20: Supplementary insurance | O20: =SUM(C20:N20) | P20: =IFERROR(AVERAGE(C20:N20),0) | Q20: =P20-B20
A21: Deductible (franchise) & co-pay | O21: =SUM(C21:N21) | P21: =IFERROR(AVERAGE(C21:N21),0) | Q21: =P21-B21
A22: Dentist / optician | O22: =SUM(C22:N22) | P22: =IFERROR(AVERAGE(C22:N22),0) | Q22: =P22-B22
A23: EXPENSES – TRANSPORT
A24: Public transport (GA / Half Fare / pass) | O24: =SUM(C24:N24) | P24: =IFERROR(AVERAGE(C24:N24),0) | Q24: =P24-B24
A25: Car: fuel / charging | O25: =SUM(C25:N25) | P25: =IFERROR(AVERAGE(C25:N25),0) | Q25: =P25-B25
A26: Car: insurance & tax | O26: =SUM(C26:N26) | P26: =IFERROR(AVERAGE(C26:N26),0) | Q26: =P26-B26
A27: Car: leasing / service | O27: =SUM(C27:N27) | P27: =IFERROR(AVERAGE(C27:N27),0) | Q27: =P27-B27
A28: Parking / bike | O28: =SUM(C28:N28) | P28: =IFERROR(AVERAGE(C28:N28),0) | Q28: =P28-B28
A29: EXPENSES – TAXES
A30: Tax reserve | O30: =SUM(C30:N30) | P30: =IFERROR(AVERAGE(C30:N30),0) | Q30: =P30-B30
A31: EXPENSES – PENSION & SAVINGS
A32: Pillar 3a | O32: =SUM(C32:N32) | P32: =IFERROR(AVERAGE(C32:N32),0) | Q32: =P32-B32
A33: Savings / emergency fund | O33: =SUM(C33:N33) | P33: =IFERROR(AVERAGE(C33:N33),0) | Q33: =P33-B33
A34: Investing (ETFs etc.) | O34: =SUM(C34:N34) | P34: =IFERROR(AVERAGE(C34:N34),0) | Q34: =P34-B34
A35: EXPENSES – EVERYDAY
A36: Groceries | O36: =SUM(C36:N36) | P36: =IFERROR(AVERAGE(C36:N36),0) | Q36: =P36-B36
A37: Toiletries & household | O37: =SUM(C37:N37) | P37: =IFERROR(AVERAGE(C37:N37),0) | Q37: =P37-B37
A38: Clothing | O38: =SUM(C38:N38) | P38: =IFERROR(AVERAGE(C38:N38),0) | Q38: =P38-B38
A39: Eating out | O39: =SUM(C39:N39) | P39: =IFERROR(AVERAGE(C39:N39),0) | Q39: =P39-B39
A40: Children / childcare | O40: =SUM(C40:N40) | P40: =IFERROR(AVERAGE(C40:N40),0) | Q40: =P40-B40
A41: Pets | O41: =SUM(C41:N41) | P41: =IFERROR(AVERAGE(C41:N41),0) | Q41: =P41-B41
...

Sheet Annual overview
A1: Annual overview
A2: Filled automatically from the «Budget» sheet.
A4: Month | B4: Income | C4: Expenses | D4: Balance | E4: Savings rate
A5: Jan | B5: =Budget!C49 | C5: =Budget!C50 | D5: =Budget!C51 | E5: =Budget!C52
A6: Feb | B6: =Budget!D49 | C6: =Budget!D50 | D6: =Budget!D51 | E6: =Budget!D52
A7: Mar | B7: =Budget!E49 | C7: =Budget!E50 | D7: =Budget!E51 | E7: =Budget!E52
A8: Apr | B8: =Budget!F49 | C8: =Budget!F50 | D8: =Budget!F51 | E8: =Budget!F52
A9: May | B9: =Budget!G49 | C9: =Budget!G50 | D9: =Budget!G51 | E9: =Budget!G52
A10: Jun | B10: =Budget!H49 | C10: =Budget!H50 | D10: =Budget!H51 | E10: =Budget!H52
A11: Jul | B11: =Budget!I49 | C11: =Budget!I50 | D11: =Budget!I51 | E11: =Budget!I52
A12: Aug | B12: =Budget!J49 | C12: =Budget!J50 | D12: =Budget!J51 | E12: =Budget!J52
A13: Sep | B13: =Budget!K49 | C13: =Budget!K50 | D13: =Budget!K51 | E13: =Budget!K52
A14: Oct | B14: =Budget!L49 | C14: =Budget!L50 | D14: =Budget!L51 | E14: =Budget!L52
A15: Nov | B15: =Budget!M49 | C15: =Budget!M50 | D15: =Budget!M51 | E15: =Budget!M52
A16: Dec | B16: =Budget!N49 | C16: =Budget!N50 | D16: =Budget!N51 | E16: =Budget!N52
A17: Total | B17: =SUM(B5:B16) | C17: =SUM(C5:C16) | D17: =SUM(D5:D16) | E17: =Budget!P52

Sheet Emergency fund
A1: Emergency fund calculator
A2: Rule of thumb: keep 3–6 months of fixed costs aside.
A4: Fixed costs per month (from budget) | B4: =Budget!B53
A5: Minimum target (3 months) | B5: =B4*3
A6: Comfortable target (6 months) | B6: =B4*6
A7: Currently in your emergency fund | B7: 0
A8: Progress towards 6-month target | B8: =IFERROR(MIN(B7/B6,1),0)
A9: Still missing | B9: =MAX(B6-B7,0)
A10: Monthly saving for the emergency fund | B10: 0
A11: Months to target | B11: =IF(B9=0,0,IFERROR(ROUNDUP(B9/B10,0),"Enter monthly saving"))

Sheet Pillar 3a
A1: Pillar 3a tracker
A2: Contributions are taken from the «Pillar 3a» row in the budget.
A4: Maximum 3a contribution this year | C4: Enter the official maximum (depends on whether you have a pension fund, see the Federal Tax Administration).
A5: Paid in so far | B5: =Budget!O32
A6: Remaining allowance | B6: =MAX(B4-B5,0)
A7: Current month (1–12) | B7: 1
A8: Needed per remaining month | B8: =IFERROR(B6/(13-B7),0)
A9: Allowance used | B9: =IFERROR(B5/B4,0)

Sheet Tax reserve
A1: Tax reserve
A2: So the tax bill never catches you off guard.
A4: Expected taxes this year | B4: 0 | C4: Tip: use your last tax bill or your canton's online tax calculator.
A5: Recommended reserve per month | B5: =B4/12
A6: Already set aside (from budget) | B6: =Budget!O30
A7: Still open | B7: =MAX(B4-B6,0)
A8: Coverage | B8: =IFERROR(B6/B4,0)
